<mujoco model="qrpfra">
    <compiler angle="degree" coordinate="local" inertiafromgeom="true" convexhull="true"/>
    <option integrator="RK4" timestep="0.02" gravity="0 0 -9.81" density="1.24"/>

    <default>
        <joint armature="1" damping="1" limited="true"/>
        <geom conaffinity="1" condim="3" density="1.24" friction="1 0.5 0.5" margin="0.01" rgba="0.8 0.6 0.4 1"/>
        
        <default class="servo_motors">
            <position ctrllimited="true" ctrlrange="-1 1" kp="90" gear="0.95"/>
        </default>
        
        <default class="joint_def">
            <joint pos="0 0 0" range="-60 60" type="hinge" damping="12"/>
        </default>

        <default class="Left_foot_Site">
            <site pos="-0.016 0.13 -0.005" type="sphere" size="0.02"/>
        </default>

        <default class="Right_foot_Site">
            <site pos="0.016 0.13 -0.005" type="sphere" size="0.02"/>
        </default>

    </default>

    <asset>
        <mesh name="main_body" file="/Users/deniz/PycharmProjects/QRPfRA_Senior_Project/QRPfRA/QRPfRA_body_m.stl"/>
        <mesh name="Left_Hind_Limb" file="/Users/deniz/PycharmProjects/QRPfRA_Senior_Project/QRPfRA/QRPfRA_left_hindlimb_m.stl"/>
        <mesh name="Left_MidLimb" file="/Users/deniz/PycharmProjects/QRPfRA_Senior_Project/QRPfRA/QRPfRA_left_midlimb_m.stl"/>
        <mesh name="Left_Wrist" file="/Users/deniz/PycharmProjects/QRPfRA_Senior_Project/QRPfRA/QRPfRA_left_wrist_m.stl"/>
        <mesh name="Right_Hind_Limb" file="/Users/deniz/PycharmProjects/QRPfRA_Senior_Project/QRPfRA/QRPfRA_right_hindlimb_m.stl"/>
        <mesh name="Right_MidLimb" file="/Users/deniz/PycharmProjects/QRPfRA_Senior_Project/QRPfRA/QRPfRA_right_midlimb_m.stl"/>
        <mesh name="Right_Wrist" file="/Users/deniz/PycharmProjects/QRPfRA_Senior_Project/QRPfRA/QRPfRA_right_wrist_m.stl"/>
        <!--mesh name="map" file="/Users/deniz/Desktop/test_metric_depth/deneme2.stl"/-->
    </asset>

    <worldbody>
        <camera name="track" mode="trackcom" pos="0 -1 0.3" xyaxes="1 0 0 0 0 1"/>
        <!--geom type="mesh" mesh="map" size="0.1"/-->

        <body name="base_link" pos="0 0 0.15">
            <geom type="mesh" mesh="main_body" mass="2" friction="0.3" contype="1" conaffinity="1" density="2400" />
            <joint limited="false" margin="0.01" name="root" pos="0 0 0" type="free" stiffness="0" damping="0" frictionloss="0" armature="0"/>

            <site name="base_link_Site" pos="0 0 0" type="box" size="0.03 0.05 0.01"/>

            <site name="head_rangefinder" pos="0 0.14 0" type="box" size="0.01 0.005 0.001" euler="-90 0 0"/>
            <site name="rear_rangefinder" pos="0 -0.155 0" type="box" size="0.01 0.005 0.001" euler="90 0 0"/>

            <site name="FL_Leg_ref" pos="-0.04 0.0875 0.015"/>
            <site name="RL_Leg_ref" pos="-0.04 -0.0975 0.015"/>
            <site name="FR_Leg_ref" pos="0.04 0.0875 0.015"/>
            <site name="RR_Leg_ref" pos="0.04 -0.0975 0.015"/>I am trying to make a

            <body name="front_Left_Hind_Limb" pos="-0.04 0.065 0.013">
                <joint class="joint_def" axis="0 1 0" name="FL_hind_to_base" />
                <geom type="mesh" mesh="Left_Hind_Limb" mass="0.150" contype="1" conaffinity="1" density="2400"/>

                <body name="front_Left_MidLimb" pos="-0.025 0.023 -0.0105" euler="90 0 0">
                    <joint class="joint_def" axis="1 0 0" name="FL_mid_to_base"/>
                    <geom type="mesh" mesh="Left_MidLimb" mass="0.350" contype="1" conaffinity="1" density="2400"/>

                    <body name="front_Left_Wrist" pos="-0.005 -0.107 -0.013" euler="-90 0 0">
                        <joint class="joint_def" axis="1 0 0" name="FL_wrist_to_mid" />
                        <geom type="mesh" mesh="Left_Wrist" mass="0.350" contype="1" conaffinity="1" density="2400"/>

                        <site name="front_Left_Wrist_Site" class="Left_foot_Site"/>

                    </body>
                </body>
            </body>

            <body name="rear_Left_Hind_Limb" pos="-0.04 -0.12 0.013">
                <joint class="joint_def" axis="0 1 0" name="RL_hind_to_base" />
                <geom type="mesh" mesh="Left_Hind_Limb" mass="0.150" contype="1" conaffinity="1" density="2400"/>

                <body name="rear_Left_MidLimb" pos="-0.025 0.023 -0.0105" euler="90 0 0">
                    <joint class="joint_def" axis="1 0 0" name="RL_mid_to_base" />
                    <geom type="mesh" mesh="Left_MidLimb" mass="0.350" contype="1" conaffinity="1" density="2400"/>

                    <body name="rear_Left_Wrist" pos="-0.005 -0.107 -0.013" euler="-90 0 0">
                        <joint class="joint_def" axis="1 0 0" name="RL_wrist_to_mid" />
                        <geom type="mesh" mesh="Left_Wrist" mass="0.350" contype="1" conaffinity="1" density="2400"/>

                        <site name="rear_Left_Wrist_Site" class="Left_foot_Site"/>

                    </body>
                </body>
            </body>

            <body name="front_Right_Hind_Limb" pos="0.04 0.065 0.013">
                <joint class="joint_def" axis="0 1 0" name="FR_hind_to_base" />
                <geom type="mesh" mesh="Right_Hind_Limb" mass="0.150" contype="1" conaffinity="1" density="2400"/>

                <body name="front_Right_MidLimb" pos="0.025 0.023 -0.0105" euler="90 0 0">
                    <joint class="joint_def" axis="1 0 0" name="FR_mid_to_base"  />
                    <geom type="mesh" mesh="Right_MidLimb" mass="0.350" contype="1" conaffinity="1" density="2400"/>

                    <body name="front_Right_Wrist" pos="0.005 -0.107 -0.013" euler="-90 0 0">
                        <joint class="joint_def" axis="1 0 0" name="FR_wrist_to_mid" />
                        <geom type="mesh" mesh="Right_Wrist" mass="0.350" contype="1" conaffinity="1" density="2400"/>

                        <site name="front_Right_Wrist_Site" class="Right_foot_Site"/>

                    </body>
                </body>
            </body>

            <body name="rear_Right_Hind_Limb" pos="0.04 -0.12 0.013">
                <joint class="joint_def" axis="0 1 0" name="RR_hind_to_base" />
                <geom type="mesh" mesh="Right_Hind_Limb" mass="0.150" contype="1" conaffinity="1" density="2400"/>

                <body name="rear_Right_MidLimb" pos="0.025 0.023 -0.0105" euler="90 0 0">
                    <joint class="joint_def" axis="1 0 0" name="RR_mid_to_base"  />
                    <geom type="mesh" mesh="Right_MidLimb" mass="0.350" contype="1" conaffinity="1" density="2400"/>

                    <body name="rear_Right_Wrist" pos="0.005 -0.107 -0.013" euler="-90 0 0">
                        <joint class="joint_def" axis="1 0 0" name="RR_wrist_to_mid" />
                        <geom type="mesh" mesh="Right_Wrist" mass="0.350" contype="1" conaffinity="1" density="2400"/>

                        <site name="rear_Right_Wrist_Site" class="Right_foot_Site"/>

                    </body>
                </body>
            </body>

        </body>

    </worldbody>

    <contact>
        <exclude body1="base_link" body2="front_Left_Hind_Limb"/>
        <exclude body1="base_link" body2="rear_Left_Hind_Limb"/>
        <exclude body1="base_link" body2="front_Right_Hind_Limb"/>
        <exclude body1="base_link" body2="rear_Right_Hind_Limb"/>

        <exclude body1="base_link" body2="front_Left_MidLimb"/>
        <exclude body1="base_link" body2="rear_Left_MidLimb"/>
        <exclude body1="base_link" body2="front_Right_MidLimb"/>
        <exclude body1="base_link" body2="rear_Right_MidLimb"/>

        <!--exclude body1="base_link" body2="front_Left_Wrist"/>
        <exclude body1="base_link" body2="rear_Left_Wrist"/>
        <exclude body1="base_link" body2="front_Right_Wrist"/>
        <exclude body1="base_link" body2="rear_Right_Wrist"/-->
        </contact>

    <actuator>
        <position class="servo_motors" joint="FL_hind_to_base" name="FL_Hind2Base"/>
        <position class="servo_motors" joint="FL_mid_to_base" name="FL_Mid2Hind"/>
        <position class="servo_motors" joint="FL_wrist_to_mid" name="FL_Wrist2Mid"/>

        <position class="servo_motors" joint="RL_hind_to_base" name="RL_Hind2Base"/>
        <position class="servo_motors" joint="RL_mid_to_base" name="RL_Mid2Hind"/>
        <position class="servo_motors" joint="RL_wrist_to_mid" name="RL_Wrist2Mid"/>

        <position class="servo_motors" joint="FR_hind_to_base" name="FR_Hind2Base"/>
        <position class="servo_motors" joint="FR_mid_to_base" name="FR_Mid2Hind"/>
        <position class="servo_motors" joint="FR_wrist_to_mid" name="FR_Wrist2Mid"/>

        <position class="servo_motors" joint="RR_hind_to_base" name="RR_Hind2Base"/>
        <position class="servo_motors" joint="RR_mid_to_base" name="RR_Mid2Hind"/>
        <position class="servo_motors" joint="RR_wrist_to_mid" name="RR_Wrist2Mid"/>
    </actuator>

    <sensor>
        <accelerometer name="accelerometer" site="base_link_Site"/> <!-- 0 1 2 -->
        <gyro name="gyroscope" site="base_link_Site"/> <!-- 3 4 5 -->
        <magnetometer name="magnetometer" site="base_link_Site"/> <!-- 6 7 8 -->

        <!--framequat name="abs_orientation_of_the_base" reftype="body" refname="base_link" objtype="site" objname="base_link_Site"/--> <!-- 9 10 11 12 -->

        <jointpos name="FL_Hind2Base_angle" joint="FL_hind_to_base"/> <!-- 9 -->
        <jointpos name="FL_Mid2Hind_angle" joint="FL_mid_to_base"/> <!-- 10 -->
        <jointpos name="FL_Wrist2Mid_angle" joint="FL_wrist_to_mid"/> <!-- 11 -->

        <jointpos name="RL_Hind2Base_angle" joint="RL_hind_to_base"/> <!-- 12 -->
        <jointpos name="RL_Mid2Hind_angle" joint="RL_mid_to_base"/> <!-- 13 -->
        <jointpos name="RL_Wrist2Mid_angle" joint="RL_wrist_to_mid"/> <!-- 14 -->

        <jointpos name="FR_Hind2Base_angle" joint="FR_hind_to_base"/> <!-- 15 -->
        <jointpos name="FR_Mid2Hind_angle" joint="FR_mid_to_base"/> <!-- 16 -->
        <jointpos name="FR_Wrist2Mid_angle" joint="FR_wrist_to_mid"/> <!-- 17 -->

        <jointpos name="RR_Hind2Base_angle" joint="RR_hind_to_base"/> <!-- 18 -->
        <jointpos name="RR_Mid2Hind_angle" joint="RR_mid_to_base"/> <!-- 19 -->
        <jointpos name="RR_Wrist2Mid_angle" joint="RR_wrist_to_mid"/> <!-- 20 -->

        <rangefinder name="head_rangefinder" site="head_rangefinder"/> <!-- 21 -->
        <rangefinder name="rear_rangefinder" site="rear_rangefinder"/> <!-- 22 -->

        <touch name="FL_foot_touch" site="front_Left_Wrist_Site" cutoff="1"/> <!-- 23 -->
        <touch name="RL_foot_touch" site="rear_Left_Wrist_Site" cutoff="1"/> <!-- 24 -->
        <touch name="FR_foot_touch" site="front_Right_Wrist_Site" cutoff="1"/> <!-- 25 -->
        <touch name="RR_foot_touch" site="rear_Right_Wrist_Site" cutoff="1"/> <!-- 26 -->

        <framequat name="abs_orientation_of_the_base" objtype="site" objname="base_link_Site"/> <!-- 27 28 29 30 -->
    </sensor>

</mujoco>
